Workbook

Sheet Sheet1
B1: G层九州厅餐位排布
B2: 序号 | C2: 姓名 | D2: 部门 | E2: 工号
B3: 九州厅1号桌 | C3: 左怡凯 | D3: OTC事业部 | E3: 2017070607
C4: 吴睿 | D4: OTC事业部 | E4: 2024120204
C5: 谭彦 | D5: OTC事业部 | E5: 2023021602
C6: 张龙 | D6: OTC事业部 | E6: 2025011305
C7: 韦晓晖 | D7: OTC事业部 | E7: 2025010201
C8: 曾放 | D8: OTC事业部 | E8: 2024022903
C9: 吴亮军 | D9: OTC事业部 | E9: 2024110106
C10: 喻建华 | D10: OTC事业部 | E10: 2018122404
C11: 杨帆 | D11: OTC事业部 | E11: 2021062301
C12: 刘珊 | D12: OTC事业部 | E12: 2007100801
B14: 九州厅2号桌 | C14: 金超 | D14: OTC事业部 | E14: 2025062431
C15: 黄朝立 | D15: OTC事业部 | E15: 2024080112
C16: 李鹏 | D16: OTC事业部 | E16: 2023101304
C17: 宋有华 | D17: OTC事业部 | E17: 2022090104
C18: 张梦南 | D18: OTC事业部 | E18: 2022070502
C19: 徐诗敏 | D19: OTC事业部 | E19: 2022021404
C20: 孙帅忠 | D20: OTC事业部 | E20: 2019031102
C21: 张守鹤 | D21: OTC事业部 | E21: 2025081803
C22: 王冬 | D22: OTC事业部 | E22: 2024010217
C23: 何慧娜 | D23: OTC事业部 | E23: 2023090502
B25: 九州厅3号桌 | C25: 王毅 | D25: OTC事业部 | E25: 2022101204
C26: 罗绮 | D26: OTC事业部 | E26: 2022072701
C27: 杨战利 | D27: OTC事业部 | E27: 2022072504
C28: 卿浩 | D28: OTC事业部 | E28: 2022041402
C29: 陈为潘 | D29: OTC事业部 | E29: 2022021114
C30: 张喜良 | D30: OTC事业部 | E30: 2019031503
C31: 沈志强 | D31: OTC事业部 | E31: 2023070303
C32: 和宝 | D32: OTC事业部 | E32: 2025090203
C33: 吴利亮 | D33: OTC事业部 | E33: 2025071602
C34: 陈吉 | D34: OTC事业部 | E34: 2025030312
B36: 九州厅4号桌 | C36: 王盛钟 | D36: OTC事业部 | E36: 2024012202
C37: 张星星 | D37: OTC事业部 | E37: 2021080101
C38: 李新美 | D38: OTC事业部 | E38: 2021040902
C39: 唐女锦 | D39: OTC事业部 | E39: 92025092203
C40: 吴雪微 | D40: OTC事业部 | E40: 92025090105
C41: 龚彪 | D41: OTC事业部 | E41: 2025082702
C42: 向柱 | D42: OTC事业部 | E42: 2024101503
C43: 彭天佑 | D43: OTC事业部 | E43: 2024062511
...
